<?xml version="1.0"?>
<robot name="barista_robot">

  <material name="red">
      <color rgba="1.0 0.0 0.0 1"/>
  </material>

  <material name="green_light">
      <color rgba="0.0 1.0 0.0 1"/>
  </material>

  <material name="green_dark">
    <color rgba="0.0 0.5 0.0 1"/>
  </material>

  <material name="blue">
      <color rgba="0.0 0.0 1.0 1"/>
  </material>

  <material name="black">
      <color rgba="0.0 0.0 0.0 1"/>
  </material>

  <material name="white">
      <color rgba="1.0 1.0 1.0 1"/>
  </material>

  <material name="box_bot_blue">
      <color rgba="0.088656 0.428691 0.491021 1"/>
  </material>

  <link name="base_link">
  </link>


  <!-- Cylinder Base -->
  <link name="chassis">
    <visual>
      <geometry>
        <cylinder length="0.155" radius="0.178"/>
      </geometry>
      <material name="blue"/>
    </visual>

    <inertial>
      <mass value="0.2"/>
      <origin rpy="0 0 0" xyz="0 0 0"/>
      <inertia ixx="0.0019846" ixy="0" ixz="0" iyy="0.0019846" iyz="0" izz="0.0031684"/>
    </inertial>

    <collision>
      <geometry>
        <cylinder length="0.155" radius="0.178"/>
      </geometry>
    </collision>

  </link>

  <joint name="base_link_joint" type="fixed">
    <origin rpy="0 0 0" xyz="0 0 0" />
    <parent link="base_link" />
    <child link="chassis" />
  </joint>

  <!-- FL standoff rods -->
  <link name="standoff_rod_front_left">
    <visual>
      <geometry>
        <cylinder length="0.22" radius="0.01"/>
      </geometry>
      <material name="white"/>
    </visual>

    <inertial>
      <mass value="0.02"/>
      <origin rpy="0 0 0" xyz="0 0 0"/>
      <inertia ixx="0.00008117" ixy="0" ixz="0" iyy="0.00008117" iyz="0" izz="0.000001"/>
    </inertial>

    <collision>
      <geometry>
        <cylinder length="0.22" radius="0.01"/>
      </geometry>
    </collision>
  </link>

  <joint name="standoff_rod_FL_to_chassis_joint" type="fixed">
    <!-- <origin rpy="0 0 0" xyz="0.025 0.05 0.0775" /> -->
    <origin rpy="0 0 0" xyz="0.05 0.12 0.1875" />

    <parent link="chassis" />
    <child link="standoff_rod_front_left" />
  </joint>
  
  <!-- BL standoff rods -->
  <link name="standoff_rod_back_left">
    <visual>
      <geometry>
        <cylinder length="0.22" radius="0.01"/>
      </geometry>
      <material name="white"/>
    </visual>

    <inertial>
      <mass value="0.02"/>
      <origin rpy="0 0 0" xyz="0 0 0"/>
      <inertia ixx="0.00008117" ixy="0" ixz="0" iyy="0.00008117" iyz="0" izz="0.000001"/>
    </inertial>

    <collision>
      <geometry>
        <cylinder length="0.22" radius="0.01"/>
      </geometry>
    </collision>
  </link>

  <joint name="standoff_rod_BL_to_chassis_joint" type="fixed">
    <!-- <origin rpy="0 0 0" xyz="0.025 0.05 0.0775" /> -->
    <origin rpy="0 0 0" xyz="-0.05 0.12 0.1875" />

    <parent link="chassis" />
    <child link="standoff_rod_back_left" />
  </joint>


  <!-- FR standoff rods -->
  <link name="standoff_rod_front_right">
    <visual>
      <geometry>
        <cylinder length="0.22" radius="0.01"/>
      </geometry>
      <material name="white"/>
    </visual>

    <inertial>
      <mass value="0.02"/>
      <origin rpy="0 0 0" xyz="0 0 0"/>
      <inertia ixx="0.00008117" ixy="0" ixz="0" iyy="0.00008117" iyz="0" izz="0.000001"/>
    </inertial>

    <collision>
      <geometry>
        <cylinder length="0.22" radius="0.01"/>
      </geometry>
    </collision>
  </link>

  <joint name="standoff_rod_FR_to_chassis_joint" type="fixed">
    <!-- <origin rpy="0 0 0" xyz="0.025 0.05 0.0775" /> -->
    <origin rpy="0 0 0" xyz="0.05 -0.12 0.1875" />

    <parent link="chassis" />
    <child link="standoff_rod_front_right" />
  </joint>
  
  <!-- BR standoff rods -->
  <link name="standoff_rod_back_right">
    <visual>
      <geometry>
        <cylinder length="0.22" radius="0.01"/>
      </geometry>
      <material name="white"/>
    </visual>

    <inertial>
      <mass value="0.02"/>
      <origin rpy="0 0 0" xyz="0 0 0"/>
      <inertia ixx="0.00008117" ixy="0" ixz="0" iyy="0.00008117" iyz="0" izz="0.000001"/>
    </inertial>

    <collision>
      <geometry>
        <cylinder length="0.22" radius="0.01"/>
      </geometry>
    </collision>
  </link>

  <joint name="standoff_rod_BR_to_chassis_joint" type="fixed">
    <origin rpy="0 0 0" xyz="-0.05 -0.12 0.1875" />
    <parent link="chassis" />
    <child link="standoff_rod_back_right" />
  </joint>

  <!-- Cup Tray -->
   <link name="cup_tray">
    <visual>
      <geometry>
        <cylinder length="0.09" radius="0.178"/>
      </geometry>
      <material name="blue"/>
    </visual>

    <inertial>
      <mass value="0.05"/>
      <origin rpy="0 0 0" xyz="0 0 0"/>
      <inertia ixx="0.0004298" ixy="0" ixz="0" iyy="0.0004298" iyz="0" izz="0.0007921"/>
    </inertial>

    <collision>
      <geometry>
        <cylinder length="0.09" radius="0.178"/>
      </geometry>
    </collision>
  </link>

  <joint name="cup_tray_to_chassis_joint" type="fixed">
    <origin rpy="0 0 0" xyz="0 0 0.3425" />
    <parent link="chassis" />
    <child link="cup_tray" />
  </joint>

  <!-- Motorized Left WHeel -->
   <link name="left_wheel">      
      <visual>
        <origin rpy="0 1.5707 1.5707" xyz="0 0 0"/>
        <geometry>
          <cylinder length="0.0206" radius="0.0352"/>
        </geometry>
        <material name="black"/>
      </visual>

    <inertial>
      <mass value="0.01"/>
      <origin rpy="0 0 0" xyz="0 0 0"/>
      <inertia ixx="0.000003451" ixy="0" ixz="0" iyy="0.000003451" iyz="0" izz="0.000006195"/>
    </inertial>

    <collision>
        <origin rpy="0 1.5707 1.5707" xyz="0 0 0"/>
        <geometry>
          <cylinder length="0.0206" radius="0.0352"/>
        </geometry>
    </collision>
  </link>

    <gazebo reference="left_wheel">
    <kp>1000000000000000000000000000.0</kp>
    <kd>1000000000000000000000000000.0</kd>
    <mu1>10.0</mu1>
    <mu2>10.0</mu2>
    <material>Gazebo/Green</material>
  </gazebo>

  <joint name="joint_left_wheel" type="continuous">
    <origin rpy="0 0 0" xyz="0 0.128 -0.0775"/>
    <child link="left_wheel"/>
    <parent link="chassis"/>
    <axis rpy="0 0 0" xyz="0 1 0"/>
    <limit effort="10000" velocity="1000"/>
    <joint_properties damping="1.0" friction="1.0"/>
  </joint>


  <!-- Motorized Right WHeel -->
   <link name="right_wheel">      
    <visual>
        <origin rpy="0 1.5707 1.5707" xyz="0 0 0"/>
        <geometry>
          <cylinder length="0.0206" radius="0.0352"/>
        </geometry>
        <material name="black"/>
    </visual>

    <inertial>
      <mass value="0.01"/>
      <origin rpy="0 0 0" xyz="0 0 0"/>
      <inertia ixx="0.000003451" ixy="0" ixz="0" iyy="0.000003451" iyz="0" izz="0.000006195"/>
    </inertial>

    <collision>
        <origin rpy="0 1.5707 1.5707" xyz="0 0 0"/>
        <geometry>
          <cylinder length="0.0206" radius="0.0352"/>
        </geometry>
    </collision>
  </link>

    <gazebo reference="right_wheel">
    <kp>1000000000000000000000000000.0</kp>
    <kd>1000000000000000000000000000.0</kd>
    <mu1>10.0</mu1>
    <mu2>10.0</mu2>
    <material>Gazebo/Orange</material>
  </gazebo>

  <joint name="joint_right_wheel" type="continuous">
    <origin rpy="0 0 0" xyz="0 -0.128 -0.0775"/>
    <child link="right_wheel"/>
    <parent link="chassis"/>
    <axis rpy="0 0 0" xyz="0 1 0"/>
    <limit effort="10000" velocity="1000"/>
    <joint_properties damping="1.0" friction="1.0"/>
  </joint>

  <!-- Caster Front Wheel -->
   <!-- yaw -->
  <link name="front_yaw_link">
    <visual>
        <origin rpy="0 1.5707 1.5707" xyz="0 0 0"/>
        <geometry>
          <cylinder length="0.005" radius="0.0352"/>
        </geometry>
        <material name="blue"/>
    </visual>

    <inertial>
      <mass value="0.01"/>
      <origin rpy="0 0 0" xyz="0 0 0"/>
      <inertia ixx="0.0000031184" ixy="0" ixz="0" iyy="0.0000031184" iyz="0" izz="0.000006195"/>
    </inertial>

    <collision>
        <origin rpy="0 1.5707 1.5707" xyz="0 0 0"/>
        <geometry>
          <cylinder length="0.005" radius="0.0352"/>
        </geometry>
    </collision>
  </link>

    <gazebo reference="front_yaw_link">
    <kp>1000000000000000000000000000.0</kp>
    <kd>1000000000000000000000000000.0</kd>
    <mu1>0.1</mu1>
    <mu2>0.1</mu2>
  </gazebo>

  <joint name="front_yaw_joint" type="continuous">
    <origin rpy="0 0 0" xyz="0.12 0 -0.0775" />
    <parent link="chassis" />
    <child link="front_yaw_link" />
    <axis xyz="0 0 1" />
    <limit effort="1000.0" velocity="100.0" />
    <dynamics damping="0.0" friction="0.1"/>
  </joint>

<!-- roll -->
  <link name="front_roll_link">
      <visual>
        <origin rpy="0 1.5707 1.5707" xyz="0 0 0"/>
        <geometry>
          <cylinder length="0.005" radius="0.0352"/>
        </geometry>
        <material name="red"/>
      </visual>

    <inertial>
      <mass value="0.01"/>
      <origin rpy="0 0 0" xyz="0 0 0"/>
      <inertia ixx="0.0000031184" ixy="0" ixz="0" iyy="0.0000031184" iyz="0" izz="0.000006195"/>
    </inertial>

    <collision>
        <origin rpy="0 1.5707 1.5707" xyz="0 0 0"/>
        <geometry>
          <cylinder length="0.005" radius="0.0352"/>
        </geometry>
    </collision>
  </link>

    <gazebo reference="front_roll_link">
    <kp>1000000000000000000000000000.0</kp>
    <kd>1000000000000000000000000000.0</kd>
    <mu1>0.1</mu1>
    <mu2>0.1</mu2>
  </gazebo>

  <joint name="front_roll_joint" type="continuous">
    <origin rpy="0 0 0" xyz="0 0 0" />
    <parent link="front_yaw_link" />
    <child link="front_roll_link" />
    <axis xyz="1 0 0" />
    <limit effort="1000.0" velocity="100.0" />
    <dynamics damping="0.0" friction="0.1"/>
  </joint>

<!-- pitch -->
  <link name="front_pitch_link">
    <visual>
      <origin rpy="0 1.5707 1.5707" xyz="0 0 0"/>
      <geometry>
        <sphere radius="0.0352"/>
      </geometry>
      <material name="green_dark"/>
    </visual>

    <inertial>
      <mass value="0.01"/>
      <origin rpy="0 0 0" xyz="0 0 0"/>
      <inertia ixx="0.00000826" ixy="0" ixz="0" iyy="00.00000826" iyz="0" izz="0.00000826"/>
    </inertial>

    <collision>
      <origin rpy="0 1.5707 1.5707" xyz="0 0 0"/>
      <geometry>
        <sphere radius="0.0352"/>
      </geometry>
    </collision>
  </link>

    <gazebo reference="front_pitch_link">
    <kp>1000000000000000000000000000.0</kp>
    <kd>1000000000000000000000000000.0</kd>
    <mu1>0.1</mu1>
    <mu2>0.1</mu2>
    <material>Gazebo/Purple</material>
  </gazebo>

  <joint name="front_pitch_joint" type="continuous">
    <origin rpy="0 0 0" xyz="0 0 0" />
    <parent link="front_roll_link" />
    <child link="front_pitch_link" />
    <axis xyz="0 1 0" />
    <limit effort="1000.0" velocity="100.0" />
    <dynamics damping="0.0" friction="0.1"/>
  </joint>


<!-- Caster Wheel Back -->
  <link name="back_yaw_link">
    <visual>
        <origin rpy="0 1.5707 1.5707" xyz="0 0 0"/>
        <geometry>
          <cylinder length="0.005" radius="0.0352"/>
        </geometry>
        <material name="blue"/>
      </visual>

    <inertial>
      <mass value="0.01"/>
      <origin rpy="0 0 0" xyz="0 0 0"/>
      <inertia ixx="0.0000031184" ixy="0" ixz="0" iyy="0.0000031184" iyz="0" izz="0.000006195"/>
    </inertial>

    <collision>
        <origin rpy="0 1.5707 1.5707" xyz="0 0 0"/>
        <geometry>
          <cylinder length="0.005" radius="0.0352"/>
        </geometry>
    </collision>
  </link>

    <gazebo reference="back_yaw_link">
    <kp>1000000000000000000000000000.0</kp>
    <kd>1000000000000000000000000000.0</kd>
    <mu1>0.1</mu1>
    <mu2>0.1</mu2>
  </gazebo>

  <joint name="back_yaw_joint" type="continuous">
    <origin rpy="0 0 0" xyz="-0.12 0 -0.0775" />
    <parent link="chassis" />
    <child link="back_yaw_link" />
    <axis xyz="0 0 1" />
    <limit effort="1000.0" velocity="100.0" />
    <dynamics damping="0.0" friction="0.1"/>
  </joint>



  <link name="back_roll_link">
      <visual>
        <origin rpy="0 1.5707 1.5707" xyz="0 0 0"/>
        <geometry>
          <cylinder length="0.005" radius="0.0352"/>
        </geometry>
        <material name="red"/>
      </visual>

    <inertial>
      <mass value="0.01"/>
      <origin rpy="0 0 0" xyz="0 0 0"/>
      <inertia ixx="0.0000031184" ixy="0" ixz="0" iyy="0.0000031184" iyz="0" izz="0.000006195"/>
    </inertial>

    <collision>
        <origin rpy="0 1.5707 1.5707" xyz="0 0 0"/>
        <geometry>
          <cylinder length="0.005" radius="0.0352"/>
        </geometry>
    </collision>
  </link>

  <gazebo reference="back_roll_link">
    <kp>1000000000000000000000000000.0</kp>
    <kd>1000000000000000000000000000.0</kd>
    <mu1>0.1</mu1>
    <mu2>0.1</mu2>
  </gazebo>

  <joint name="back_roll_joint" type="continuous">
    <origin rpy="0 0 0" xyz="0 0 0" />
    <parent link="back_yaw_link" />
    <child link="back_roll_link" />
    <axis xyz="1 0 0" />
    <limit effort="1000.0" velocity="100.0" />
    <dynamics damping="0.0" friction="0.1"/>
  </joint>



  <link name="back_pitch_link">
    <visual>
      <origin rpy="0 1.5707 1.5707" xyz="0 0 0"/>
      <geometry>
        <sphere radius="0.0352"/>
      </geometry>
      <material name="green_light"/>
    </visual>

    <inertial>
      <mass value="0.01"/>
      <origin rpy="0 0 0" xyz="0 0 0"/>
      <inertia ixx="0.00000826" ixy="0" ixz="0" iyy="00.00000826" iyz="0" izz="0.00000826"/>
    </inertial>

    <collision>
      <origin rpy="0 1.5707 1.5707" xyz="0 0 0"/>
      <geometry>
        <sphere radius="0.0352"/>
      </geometry>
    </collision>
  </link>

  <gazebo reference="back_pitch_link">
    <kp>1000000000000000000000000000.0</kp>
    <kd>1000000000000000000000000000.0</kd>
    <mu1>0.1</mu1>
    <mu2>0.1</mu2>
    <material>Gazebo/Yellow</material>
  </gazebo>

  <joint name="back_pitch_joint" type="continuous">
    <origin rpy="0 0 0" xyz="0 0 0" />
    <parent link="back_roll_link" />
    <child link="back_pitch_link" />
    <axis xyz="0 1 0" />
    <limit effort="1000.0" velocity="100.0" />
    <dynamics damping="0.0" friction="0.1"/>
  </joint>

  <!-- Laser Position Control-->

    <link name="laser_scan_link">
        <visual>
        <origin rpy="0 0 0" xyz="0 0 0"/>
        <geometry> 
            <mesh filename="package://barista_robot_description/meshes/hokuyo_urg_04lx.dae" scale="1.0 1.0 1.0"/>
        </geometry>
        </visual>

        <collision>
        <origin rpy="0 0 0" xyz="0 0 0.0204"/>
        <geometry>
            <box size="0.074986 0.074935 0.0408"/>
        </geometry>
        </collision>

        <inertial>

        <mass value="0.01"/>
        <origin rpy="0 0 0" xyz="0 0 0.0204"/>
        <inertia ixx="6.066578520833334e-06" ixy="0" ixz="0" iyy="6.072950163333333e-06" iyz="0" izz="9.365128684166666e-06"/>
        </inertial>
    </link>

    <joint name="laser_scan_link_joint" type="fixed">
        <origin rpy="0 0 0" xyz="0.0 0.0 0.0775"/>
        <parent link="chassis"/>
        <child link="laser_scan_link"/>
    </joint>

    <link name="laser_scan_frame">
    </link>

    <joint name="laser_scan_frame_joint" type="fixed">
        <origin rpy="0 0 0" xyz="0 0 0.03"/>
        <parent link="laser_scan_link"/>
        <child link="laser_scan_frame"/>
        <axis xyz="0 0 0"/>
    </joint>


<!-- Plug-ins-->

  <!-- JOINT PUBLISHER -->
  <gazebo>
    <plugin name="box_bot_joint_state" filename="libgazebo_ros_joint_state_publisher.so">
      <ros>
          <remapping>~/out:=joint_states</remapping>
      </ros>
      <update_rate>30</update_rate>

      <joint_name>joint_left_wheel</joint_name>
      <joint_name>joint_right_wheel</joint_name>
      <joint_name>front_yaw_joint</joint_name>
      <joint_name>back_yaw_joint</joint_name>
      <joint_name>front_roll_joint</joint_name>
      <joint_name>back_roll_joint</joint_name>
      <joint_name>front_pitch_joint</joint_name>
      <joint_name>back_pitch_joint</joint_name>
      
    </plugin>
  </gazebo>

  <!-- Differential drive -->
  <gazebo>
    <plugin filename="libgazebo_ros_diff_drive.so" name="differential_drive_controller">

      <!-- wheels -->
      <left_joint>joint_left_wheel</left_joint>
      <right_joint>joint_right_wheel</right_joint>

      <!-- kinematics -->
      <wheel_separation>0.1</wheel_separation>
      <wheel_diameter>0.07</wheel_diameter>

      <!-- limits -->
      <max_wheel_torque>1.0</max_wheel_torque>
      <max_wheel_acceleration>2.0</max_wheel_acceleration>

      <!-- output -->
      <publish_odom>true</publish_odom>
      <publish_odom_tf>true</publish_odom_tf>

      <odometry_frame>odom</odometry_frame>
      <robot_base_frame>base_link</robot_base_frame>

    </plugin>
  </gazebo>

  <!-- Coloring Links within Gazebo  -->
  <gazebo reference="chassis">
    <material>Gazebo/Blue</material>
    </gazebo>

    <gazebo reference="cup_tray">
        <material>Gazebo/Blue</material>
    </gazebo>

    <gazebo reference="standoff_rod_front_left">
        <material>Gazebo/White</material>
    </gazebo>

    <gazebo reference="standoff_rod_front_right">
        <material>Gazebo/White</material>
    </gazebo>

    <gazebo reference="standoff_rod_back_left">
        <material>Gazebo/White</material>
    </gazebo>

    <gazebo reference="standoff_rod_back_right">
        <material>Gazebo/White</material>
    </gazebo>

    <gazebo reference="back_yaw_link">
        <material>Gazebo/Blue</material>
    </gazebo>

    <gazebo reference="back_roll_link">
        <material>Gazebo/Red</material>
    </gazebo>
</robot>